2023-04-14 09:48:25,784 INFO    StreamThr :759133 [internal.py:wandb_internal():92] W&B internal server running at pid: 759133, started at: 2023-04-14 09:48:25.764614
2023-04-14 09:48:25,785 DEBUG   HandlerThread:759133 [handler.py:handle_request():141] handle_request: status
2023-04-14 09:48:25,787 DEBUG   SenderThread:759133 [sender.py:send_request():249] send_request: status
2023-04-14 09:48:25,789 DEBUG   SenderThread:759133 [sender.py:send():235] send: header
2023-04-14 09:48:25,789 INFO    WriterThread:759133 [datastore.py:open_for_write():77] open: /gpfsdswork/projects/rech/rnz/uyc98hc/solo-learn/wandb/run-20230414_094825-2pbbjnsv/run-2pbbjnsv.wandb
2023-04-14 09:48:25,789 DEBUG   SenderThread:759133 [sender.py:send():235] send: run
2023-04-14 09:48:55,785 DEBUG   HandlerThread:759133 [handler.py:handle_request():141] handle_request: shutdown
2023-04-14 09:48:55,785 INFO    HandlerThread:759133 [handler.py:finish():790] shutting down handler
2023-04-14 09:48:55,796 INFO    WriterThread:759133 [datastore.py:close():281] close: /gpfsdswork/projects/rech/rnz/uyc98hc/solo-learn/wandb/run-20230414_094825-2pbbjnsv/run-2pbbjnsv.wandb
2023-04-14 09:48:59,209 ERROR   SenderThread:759133 [retry.py:__call__():126] Retry attempt failed:
Traceback (most recent call last):
  File "/gpfslocalsup/pub/anaconda-py3/2021.05/envs/pytorch-gpu-1.11.0+py3.9.12/lib/python3.9/site-packages/urllib3/connection.py", line 174, in _new_conn
    conn = connection.create_connection(
  File "/gpfslocalsup/pub/anaconda-py3/2021.05/envs/pytorch-gpu-1.11.0+py3.9.12/lib/python3.9/site-packages/urllib3/util/connection.py", line 95, in create_connection
    raise err
  File "/gpfslocalsup/pub/anaconda-py3/2021.05/envs/pytorch-gpu-1.11.0+py3.9.12/lib/python3.9/site-packages/urllib3/util/connection.py", line 85, in create_connection
    sock.connect(sa)
socket.timeout: timed out

During handling of the above exception, another exception occurred:

Traceback (most recent call last):
  File "/gpfslocalsup/pub/anaconda-py3/2021.05/envs/pytorch-gpu-1.11.0+py3.9.12/lib/python3.9/site-packages/urllib3/connectionpool.py", line 703, in urlopen
    httplib_response = self._make_request(
  File "/gpfslocalsup/pub/anaconda-py3/2021.05/envs/pytorch-gpu-1.11.0+py3.9.12/lib/python3.9/site-packages/urllib3/connectionpool.py", line 386, in _make_request
    self._validate_conn(conn)
  File "/gpfslocalsup/pub/anaconda-py3/2021.05/envs/pytorch-gpu-1.11.0+py3.9.12/lib/python3.9/site-packages/urllib3/connectionpool.py", line 1040, in _validate_conn
    conn.connect()
  File "/gpfslocalsup/pub/anaconda-py3/2021.05/envs/pytorch-gpu-1.11.0+py3.9.12/lib/python3.9/site-packages/urllib3/connection.py", line 358, in connect
    self.sock = conn = self._new_conn()
  File "/gpfslocalsup/pub/anaconda-py3/2021.05/envs/pytorch-gpu-1.11.0+py3.9.12/lib/python3.9/site-packages/urllib3/connection.py", line 179, in _new_conn
    raise ConnectTimeoutError(
urllib3.exceptions.ConnectTimeoutError: (<urllib3.connection.HTTPSConnection object at 0x147a21c04ee0>, 'Connection to api.wandb.ai timed out. (connect timeout=10)')

During handling of the above exception, another exception occurred:

Traceback (most recent call last):
  File "/gpfslocalsup/pub/anaconda-py3/2021.05/envs/pytorch-gpu-1.11.0+py3.9.12/lib/python3.9/site-packages/requests/adapters.py", line 440, in send
    resp = conn.urlopen(
  File "/gpfslocalsup/pub/anaconda-py3/2021.05/envs/pytorch-gpu-1.11.0+py3.9.12/lib/python3.9/site-packages/urllib3/connectionpool.py", line 785, in urlopen
    retries = retries.increment(
  File "/gpfslocalsup/pub/anaconda-py3/2021.05/envs/pytorch-gpu-1.11.0+py3.9.12/lib/python3.9/site-packages/urllib3/util/retry.py", line 592, in increment
    raise MaxRetryError(_pool, url, error or ResponseError(cause))
urllib3.exceptions.MaxRetryError: HTTPSConnectionPool(host='api.wandb.ai', port=443): Max retries exceeded with url: /graphql (Caused by ConnectTimeoutError(<urllib3.connection.HTTPSConnection object at 0x147a21c04ee0>, 'Connection to api.wandb.ai timed out. (connect timeout=10)'))

During handling of the above exception, another exception occurred:

Traceback (most recent call last):
  File "/gpfslocalsup/pub/anaconda-py3/2021.05/envs/pytorch-gpu-1.11.0+py3.9.12/lib/python3.9/site-packages/wandb/sdk/lib/retry.py", line 102, in __call__
    result = self._call_fn(*args, **kwargs)
  File "/gpfslocalsup/pub/anaconda-py3/2021.05/envs/pytorch-gpu-1.11.0+py3.9.12/lib/python3.9/site-packages/wandb/sdk/internal/internal_api.py", line 141, in execute
    return self.client.execute(*args, **kwargs)
  File "/gpfslocalsup/pub/anaconda-py3/2021.05/envs/pytorch-gpu-1.11.0+py3.9.12/lib/python3.9/site-packages/wandb/vendor/gql-0.2.0/wandb_gql/client.py", line 52, in execute
    result = self._get_result(document, *args, **kwargs)
  File "/gpfslocalsup/pub/anaconda-py3/2021.05/envs/pytorch-gpu-1.11.0+py3.9.12/lib/python3.9/site-packages/wandb/vendor/gql-0.2.0/wandb_gql/client.py", line 60, in _get_result
    return self.transport.execute(document, *args, **kwargs)
  File "/gpfslocalsup/pub/anaconda-py3/2021.05/envs/pytorch-gpu-1.11.0+py3.9.12/lib/python3.9/site-packages/wandb/vendor/gql-0.2.0/wandb_gql/transport/requests.py", line 38, in execute
    request = requests.post(self.url, **post_args)
  File "/gpfslocalsup/pub/anaconda-py3/2021.05/envs/pytorch-gpu-1.11.0+py3.9.12/lib/python3.9/site-packages/requests/api.py", line 117, in post
    return request('post', url, data=data, json=json, **kwargs)
  File "/gpfslocalsup/pub/anaconda-py3/2021.05/envs/pytorch-gpu-1.11.0+py3.9.12/lib/python3.9/site-packages/requests/api.py", line 61, in request
    return session.request(method=method, url=url, **kwargs)
  File "/gpfslocalsup/pub/anaconda-py3/2021.05/envs/pytorch-gpu-1.11.0+py3.9.12/lib/python3.9/site-packages/requests/sessions.py", line 529, in request
    resp = self.send(prep, **send_kwargs)
  File "/gpfslocalsup/pub/anaconda-py3/2021.05/envs/pytorch-gpu-1.11.0+py3.9.12/lib/python3.9/site-packages/requests/sessions.py", line 645, in send
    r = adapter.send(request, **kwargs)
  File "/gpfslocalsup/pub/anaconda-py3/2021.05/envs/pytorch-gpu-1.11.0+py3.9.12/lib/python3.9/site-packages/requests/adapters.py", line 507, in send
    raise ConnectTimeout(e, request=request)
requests.exceptions.ConnectTimeout: HTTPSConnectionPool(host='api.wandb.ai', port=443): Max retries exceeded with url: /graphql (Caused by ConnectTimeoutError(<urllib3.connection.HTTPSConnection object at 0x147a21c04ee0>, 'Connection to api.wandb.ai timed out. (connect timeout=10)'))
